Workbook

Sheet PICK AND ROLL
B2: PROGRAMA PICK AND ROLL
B5: FECHA | C5: =TODAY()
B7: ROT PRESENTADOR 1 | C7: Kiko Ruiz | E7: RÓTULOS INVITADO PICK AND ROLL
E8: INVITADO 1
E9: (Nombre Minúsculas)-> | F9: Javier R. Walls
B10: ROT PRESENTADOR 2 | E10: (Cargo Minúsculas)-> | F10: Entrenador baloncesto
E11: CARGO
E12: INVITADO 2
B13: ROT PRESENTADOR 3 | E13: (Nombre Minúsculas)-> | F13: José Luis Camacho
E14: (Cargo Minúsculas)-> | F14: Médico deportivo
B16: ROT PRESENTADOR 4 | E16: INVITADO 3
E17: (Nombre Minúsculas)->
E18: (Cargo Minúsculas)->
B19: ROT PRESENTADOR 5
E20: INVITADO 4
E21: (Nombre Minúsculas)->
B22: ROT PRESENTADOR 6 | E22: (Cargo Minúsculas)->
E24: INVITADO 5
B25: ROT PRESENTADOR 7 | E25: (Nombre Minúsculas)-> | F25: Invi 5
E26: (Cargo Minúsculas)-> | F26: Cargo 5
E28: INVITADO 6
E29: (Nombre Minúsculas)-> | F29: Invi 6
C30: ENTRE IMPOTENCIA Y LA DESILUSIÓN | E30: (Cargo Minúsculas)-> | F30: Cargo 6
C31: Huelva Comercio saca a relucir su crisis ante el líder. A Vítaly Badajoz le basta con medio partido para sentenciar el encuentro
E32: INVITADO 7
E33: (Nombre Minúsculas)-> | F33: Invi 7
C34: UN PROYECTO QUE HACE AGUAS | E34: (Cargo Minúsculas)-> | F34: Cargo 7
C35: La desapacirión de algunos jugadores deja en situación precaria a una plantilla con pocos recursos para competir.
E36: INVITADO 8
E37: (Nombre Minúsculas)-> | F37: Invi 8
C38: SEGUNDA VUELTA EN CAÍDA LIBRE | E38: (Cargo Minúsculas)-> | F38: Cargo 8
C39: El equipo de Antonio Quintero solo ha sido capaz de vencer en Aljaraque en las últimas 6 jornadas de la fase regular
E40: INVITADO 9
E41: (Nombre Minúsculas)-> | F41: Invi 9
E42: (Cargo Minúsculas)-> | F42: Cargo 9
E44: INVITADO 10
E45: (Nombre Minúsculas)-> | F45: Invi 10
E46: (Cargo Minúsculas)-> | F46: Cargo 10
E48: INVITADO 11
E49: (Nombre Minúsculas)-> | F49: Invi 11
...

Sheet RESULTADOS JORNADA
A1: RESULTADOS N1 ANDALUZA
A2: CB GIBRALEÓN - CB CIUDAD DE PALOS | B2: 80-60
A3: ATICA SEVILLA CB CORIA - CB LEPE ALIUS | B3: 89-60
A4: BARNETO MODAS LA PALMA 95 - NAUTICO SEVILLA | B4: 74-56
A5: CD BALONCESTO HUELVA LA LUZ - AVATEL ÉCIJA | B5: 67-100
A6: CB FRESAS - XEREZ CLUB DEPORTIVO | B6: 59-64
A7: CDBC PILAS - CIRCULO MERCANTIL | B7: 57-86
A8: RC LABRADORES - AD REM ONUBA | B8: APLAZADO
A12: RESULTADOS TERCERA FEB
A13: CBA SPAIN - DEHESAS R. PEÑARROYA | B13: 54-87
A14: HACHE P. MORALEJA - BAUBLOCK GYMNÁSTICA | B14: 58-81
A15: INSOLAC CB ALCALÁ - BOSCO MÉRIDA PH | B15: 50-83
A16: SAN ANTONIO CÁCERES - CB DOS HERMANAS | B16: 62-73
A17: HUELVA COMERCIO VIRIDIS - BC BADAJOZ | B17: 52-73
A18: CB SAN FERNANDO - LITHIUM I. SAGRADO | B18: 85-79
A19: ATICA SEVILLA CB CORIA - S.D. ALJARAQUE | B19: APLAZADO

Sheet CLASIFICACION
A1: CLASIFICACION N1 ANDALUZA | B1: PJ | C1: PG | D1: PP | E1: PTS
A2: 1 | B2: AD REM ONUBA | C2: 17 | D2: 16 | E2: 1 | F2: 33
A3: 2 | B3: CIRCULO MERCANTIL | C3: 18 | D3: 15 | E3: 3 | F3: 33
A4: 3 | B4: ATICA SEVILLA CB CORIA | C4: 18 | D4: 12 | E4: 6 | F4: 30
A5: 4 | B5: CB FRESAS - SAFA REYES | C5: 19 | D5: 10 | E5: 9 | F5: 29
A6: 5 | B6: BARNETO MODAS LA PALMA 95 | C6: 17 | D6: 12 | E6: 5 | F6: 29
A7: 6 | B7: CLUB NAUTICO SEVILLA | C7: 18 | D7: 10 | E7: 8 | F7: 28
A8: 7 | B8: CB LEPE ALIUS EL JAMÓN | C8: 17 | D8: 10 | E8: 7 | F8: 27
A9: 8 | B9: XEREZ CLUB DEPORTIVO | C9: 19 | D9: 8 | E9: 11 | F9: 27
A10: 9 | B10: CDBC PILAS | C10: 17 | D10: 9 | E10: 8 | F10: 26
A11: 10 | B11: CB GIBRALEÓN | C11: 18 | D11: 8 | E11: 10 | F11: 26
A12: 11 | B12: RC LABRADORES | C12: 16 | D12: 8 | E12: 8 | F12: 24
A13: 12 | B13: ÉCIJA BASKET | C13: 18 | D13: 5 | E13: 13 | F13: 23
... A15: 14 | B15: HUELVA LA LUZ | C15: 18 | D15: 0 | E15: 18 | F15: 18
A17: CLASIFICACION TERCERA FEB
A18: 1 | B18: VÍTALY LA MAR BC BADAJOZ | C18: 18 | D18: 16 | E18: 2 | F18: 34
A19: 2 | B19: BOSCO MÉRIDA PH | C19: 18 | D19: 14 | E19: 4 | F19: 32
A20: 3 | B20: BAUBLOCK GYMNÁSTICA | C20: 19 | D20: 13 | E20: 6 | F20: 32
A21: 4 | B21: CB SAN FERNANDO | C21: 19 | D21: 11 | E21: 8 | F21: 30
A22: 5 | B22: SAN ANTONIO CÁCERES | C22: 18 | D22: 11 | E22: 7 | F22: 29
A23: 6 | B23: LITHIUM IBERIA SAGRADO | C23: 18 | D23: 11 | E23: 7 | F23: 29
A24: 7 | B24: HUELVA COMERCIO VIRIDIS | C24: 18 | D24: 10 | E24: 8 | F24: 28
A25: 8 | B25: ATICA SEVILLA CB CORIA | C25: 17 | D25: 10 | E25: 7 | F25: 27
A26: 9 | B26: INSOLAC CB ALCALÁ CAJA87 | C26: 18 | D26: 8 | E26: 10 | F26: 26
A27: 10 | B27: D.R. PEÑARROYA | C27: 18 | D27: 7 | E27: 11 | F27: 25
A28: 11 | B28: EIFFAGE CB DOS HERMANAS | C28: 17 | D28: 6 | E28: 11 | F28: 23
A29: 12 | B29: CBA SPAIN | C29: 18 | D29: 3 | E29: 15 | F29: 21
... A31: 14 | B31: S.D. ALJARAQUE | C31: 16 | D31: 3 | E31: 13 | F31: 19

Sheet PRÓXIMA JORNADA
A1: PRÓXIMA JORNADA N1 ANDALUZA | B1: Fecha y Hora
A2: CD BALONCESTO HUELVA LA LUZ - AD REM ONUBA | B2: 25/02/26 21:30
A3: MAQUINARIAS DEL ODIEL CB GIBRALEÓN - ATICA SEVILLA CB CORIA | B3: 28/02/26 18:00
A4: CB CIUDAD DE PALOS - CB FRESAS - SAFA REYES SEVILLA | B4: 23/02/26 21:00
A5: XEREZ CLUB DEPORTIVO - CD BALONCESTO HUELVA LA LUZ | B5: 01/03/26 12:00
A6: AVATEL TELECOM ÉCIJA BASKET - IBERIAN INSURANCE GROUP CDBC PILAS | B6: 28/02/26 19:00
A7: AD REM ONUBA - BARNETO MODAS LA PALMA 95 | B7: 28/02/26 19:00
A8: CLUB NAUTICO SEVILLA - CB LEPE ALIUS EL JAMÓN | B8: 25/02/26 20:45
A12: PRÓXIMA JORNADA TERCERA FEB | B12: Fecha y Hora
A13: CBA SPAIN - D.R. PEÑARROYA | B13: 54 - 87 | C13: 21/02/2026
A14: HACHE P. MORALEJA - BAUBLOCK GYMNÁSTICA | B14: 58 - 81 | C14: 21/02/2026
A15: I. CB ALCALÁ CAJA87 - BOSCO MÉRIDA | B15: 50 - 83 | C15: 21/02/2026
A16: SAN ANTONIO CÁCERES - CB DOS HERMANAS | B16: 62 - 73 | C16: 22/02/2026
A17: HUELVA COMERCIO VIRIDIS - BC BADAJOZ | B17: 52 - 73 | C17: 22/02/2026
A18: CB SAN FERNANDO - SAGRADO CORAZÓN | B18: 85 - 79 | C18: 22/02/2026
A19: CB CORIA - S.D. ALJARAQUE | B19: APLAZADO | C19: 26/03/2026

Sheet INPUTS PROXIMA JORNADA
A1: PARTIDO 1 | B1: FECHA 1 | C1: PARTIDO 2 | D1: FECHA 2 | E1: PARTIDO 3 | F1: FECHA 3 | G1: PARTIDO 4 | H1: FECHA 4 | I1: PARTIDO 5 | J1: FECHA 5 | K1: PARTIDO 6 | L1: FECHA 6 | M1: PARTIDO 7 | N1: FECHA 7 | O1: PARTIDO HC 1 | P1: FECHA HC 1 | Q1: PARTIDO HC 2 | R1: FECHA HC 2 | S1: PARTIDO HC 3 | T1: FECHA HC 3 | U1: PARTIDO HC 4 | V1: FECHA HC 4 | W1: PARTIDO HC 5 | X1: FECHA HC 5 | Y1: PARTIDO HC 6 | Z1: FECHA HC 6 | AA1: PARTIDO HC 7 | AB1: FECHA HC 7
A2: ='PRÓXIMA JORNADA'!A2 | B2: ='PRÓXIMA JORNADA'!B2 | C2: ='PRÓXIMA JORNADA'!A3 | D2: ='PRÓXIMA JORNADA'!B3 | E2: ='PRÓXIMA JORNADA'!A4 | F2: ='PRÓXIMA JORNADA'!B4 | G2: ='PRÓXIMA JORNADA'!A5 | H2: ='PRÓXIMA JORNADA'!B5 | I2: ='PRÓXIMA JORNADA'!A6 | J2: ='PRÓXIMA JORNADA'!B6 | K2: ='PRÓXIMA JORNADA'!A7 | L2: ='PRÓXIMA JORNADA'!B7 | M2: ='PRÓXIMA JORNADA'!A8 | N2: ='PRÓXIMA JORNADA'!B8 | O2: ='PRÓXIMA JORNADA'!A13 | P2: ='PRÓXIMA JORNADA'!B13 | Q2: ='PRÓXIMA JORNADA'!A14 | R2: ='PRÓXIMA JORNADA'!B14 | S2: ='PRÓXIMA JORNADA'!A15 | T2: ='PRÓXIMA JORNADA'!B15 | U2: ='PRÓXIMA JORNADA'!A16 | V2: ='PRÓXIMA JORNADA'!B16 | W2: ='PRÓXIMA JORNADA'!A17 | X2: ='PRÓXIMA JORNADA'!B17 | Y2: ='PRÓXIMA JORNADA'!A18 | Z2: ='PRÓXIMA JORNADA'!B18 | AA2: ='PRÓXIMA JORNADA'!A19 | AB2: ='PRÓXIMA JORNADA'!B19

Sheet INPUTS CLASIFICACION N1
A1: EQUIPO 1 | B1: JUGADOS 1 | C1: GANADOS 1 | D1: PERDIDOS 1 | E1: PUNTOS 1 | F1: EQUIPO 2 | G1: JUGADOS 2 | H1: GANADOS 2 | I1: PERDIDOS 2 | J1: PUNTOS 2 | K1: EQUIPO 3 | L1: JUGADOS 3 | M1: GANADOS 3 | N1: PERDIDOS 3 | O1: PUNTOS 3 | P1: EQUIPO 4 | Q1: JUGADOS 4 | R1: GANADOS 4 | S1: PERDIDOS 4 | T1: PUNTOS 4 | U1: EQUIPO 5 | V1: JUGADOS 5 | W1: GANADOS 5 | X1: PERDIDOS 5 | Y1: PUNTOS 5 | Z1: EQUIPO 6 | AA1: JUGADOS 6 | AB1: GANADOS 6 | AC1: PERDIDOS 6 | AD1: PUNTOS 6 | AE1: EQUIPO 7 | AF1: JUGADOS 7 | AG1: GANADOS 7 | AH1: PERDIDOS 7 | AI1: PUNTOS 7 | AJ1: EQUIPO 8 | AK1: JUGADOS 8 | AL1: GANADOS 8 | AM1: PERDIDOS 8 | AN1: PUNTOS 8 | AO1: EQUIPO 9 | AP1: JUGADOS 9 | AQ1: GANADOS 9 | AR1: PERDIDOS 9 | AS1: PUNTOS 9 | AT1: EQUIPO 10 | AU1: JUGADOS 10 | AV1: GANADOS 10 | AW1: PERDIDOS 10 | AX1: PUNTOS 10 | AY1: EQUIPO 11 | AZ1: JUGADOS 11 | BA1: GANADOS 11 | BB1: PERDIDOS 11 | BC1: PUNTOS 11 | BD1: EQUIPO 12 | BE1: JUGADOS 12 | BF1: GANADOS 12 | BG1: PERDIDOS 12 | BH1: PUNTOS 12 | BI1: EQUIPO 13 | BJ1: JUGADOS 13 | BK1: GANADOS 13 | BL1: PERDIDOS 13 | BM1: PUNTOS 13 | BN1: EQUIPO 14 | BO1: JUGADOS 14 | BP1: GANADOS 14 | BQ1: PERDIDOS 14 | BR1: PUNTOS 14
A2: =CLASIFICACION!A2 | B2: =CLASIFICACION!B2 | C2: =CLASIFICACION!C2 | D2: =CLASIFICACION!D2 | E2: =CLASIFICACION!E2 | F2: =CLASIFICACION!A3 | G2: =CLASIFICACION!B3 | H2: =CLASIFICACION!C3 | I2: =CLASIFICACION!D3 | J2: =CLASIFICACION!E3 | K2: =CLASIFICACION!A4 | L2: =CLASIFICACION!B4 | M2: =CLASIFICACION!C4 | N2: =CLASIFICACION!D4 | O2: =CLASIFICACION!E4 | P2: =CLASIFICACION!A5 | Q2: =CLASIFICACION!B5 | R2: =CLASIFICACION!C5 | S2: =CLASIFICACION!D5 | T2: =CLASIFICACION!E5 | U2: =CLASIFICACION!A6 | V2: =CLASIFICACION!B6 | W2: =CLASIFICACION!C6 | X2: =CLASIFICACION!D6 | Y2: =CLASIFICACION!E6 | Z2: =CLASIFICACION!A7 | AA2: =CLASIFICACION!B7 | AB2: =CLASIFICACION!C7 | AC2: =CLASIFICACION!D7 | AD2: =CLASIFICACION!E7 | AE2: =CLASIFICACION!A8 | AF2: =CLASIFICACION!B8 | AG2: =CLASIFICACION!C8 | AH2: =CLASIFICACION!D8 | AI2: =CLASIFICACION!E8 | AJ2: =CLASIFICACION!A9 | AK2: =CLASIFICACION!B9 | AL2: =CLASIFICACION!C9 | AM2: =CLASIFICACION!D9 | AN2: =CLASIFICACION!E9 | AO2: =CLASIFICACION!A10 | AP2: =CLASIFICACION!B10 | AQ2: =CLASIFICACION!C10 | AR2: =CLASIFICACION!D10 | AS2: =CLASIFICACION!E10 | AT2: =CLASIFICACION!A11 | AU2: =CLASIFICACION!B11 | AV2: =CLASIFICACION!C11 | AW2: =CLASIFICACION!D11 | AX2: =CLASIFICACION!E11 | AY2: =CLASIFICACION!A12 | AZ2: =CLASIFICACION!B12 | BA2: =CLASIFICACION!C12 | BB2: =CLASIFICACION!D12 | BC2: =CLASIFICACION!E12 | BD2: =CLASIFICACION!A13 | BE2: =CLASIFICACION!B13 | BF2: =CLASIFICACION!C13 | BG2: =CLASIFICACION!D13 | BH2: =CLASIFICACION!E13 | BI2: =CLASIFICACION!A14 | BJ2: =CLASIFICACION!B14 | BK2: =CLASIFICACION!C14 | BL2: =CLASIFICACION!D14 | BM2: =CLASIFICACION!E14 | BN2: =CLASIFICACION!A15 | BO2: =CLASIFICACION!B15 | BP2: =CLASIFICACION!C15 | BQ2: =CLASIFICACION!D15 | BR2: =CLASIFICACION!E15

Sheet INPUTS CLASIFICACION TERCERA FE
A1: EQUIPO 1 | B1: JUGADOS 1 | C1: GANADOS 1 | D1: PERDIDOS 1 | E1: PUNTOS 1 | F1: EQUIPO 2 | G1: JUGADOS 2 | H1: GANADOS 2 | I1: PERDIDOS 2 | J1: PUNTOS 2 | K1: EQUIPO 3 | L1: JUGADOS 3 | M1: GANADOS 3 | N1: PERDIDOS 3 | O1: PUNTOS 3 | P1: EQUIPO 4 | Q1: JUGADOS 4 | R1: GANADOS 4 | S1: PERDIDOS 4 | T1: PUNTOS 4 | U1: EQUIPO 5 | V1: JUGADOS 5 | W1: GANADOS 5 | X1: PERDIDOS 5 | Y1: PUNTOS 5 | Z1: EQUIPO 6 | AA1: JUGADOS 6 | AB1: GANADOS 6 | AC1: PERDIDOS 6 | AD1: PUNTOS 6 | AE1: EQUIPO 7 | AF1: JUGADOS 7 | AG1: GANADOS 7 | AH1: PERDIDOS 7 | AI1: PUNTOS 7 | AJ1: EQUIPO 8 | AK1: JUGADOS 8 | AL1: GANADOS 8 | AM1: PERDIDOS 8 | AN1: PUNTOS 8 | AO1: EQUIPO 9 | AP1: JUGADOS 9 | AQ1: GANADOS 9 | AR1: PERDIDOS 9 | AS1: PUNTOS 9 | AT1: EQUIPO 10 | AU1: JUGADOS 10 | AV1: GANADOS 10 | AW1: PERDIDOS 10 | AX1: PUNTOS 10 | AY1: EQUIPO 11 | AZ1: JUGADOS 11 | BA1: GANADOS 11 | BB1: PERDIDOS 11 | BC1: PUNTOS 11 | BD1: EQUIPO 12 | BE1: JUGADOS 12 | BF1: GANADOS 12 | BG1: PERDIDOS 12 | BH1: PUNTOS 12 | BI1: EQUIPO 13 | BJ1: JUGADOS 13 | BK1: GANADOS 13 | BL1: PERDIDOS 13 | BM1: PUNTOS 13 | BN1: EQUIPO 14 | BO1: JUGADOS 14 | BP1: GANADOS 14 | BQ1: PERDIDOS 14 | BR1: PUNTOS 14
A2: =CLASIFICACION!A19 | B2: =CLASIFICACION!B19 | C2: =CLASIFICACION!C19 | D2: =CLASIFICACION!D19 | E2: =CLASIFICACION!E19 | F2: =CLASIFICACION!A20 | G2: =CLASIFICACION!B20 | H2: =CLASIFICACION!C20 | I2: =CLASIFICACION!D20 | J2: =CLASIFICACION!E20 | K2: =CLASIFICACION!A21 | L2: =CLASIFICACION!B21 | M2: =CLASIFICACION!C21 | N2: =CLASIFICACION!D21 | O2: =CLASIFICACION!E21 | P2: =CLASIFICACION!A22 | Q2: =CLASIFICACION!B22 | R2: =CLASIFICACION!C22 | S2: =CLASIFICACION!D22 | T2: =CLASIFICACION!E22 | U2: =CLASIFICACION!A23 | V2: =CLASIFICACION!B23 | W2: =CLASIFICACION!C23 | X2: =CLASIFICACION!D23 | Y2: =CLASIFICACION!E23 | Z2: =CLASIFICACION!A24 | AA2: =CLASIFICACION!B25 | AB2: =CLASIFICACION!C25 | AC2: =CLASIFICACION!D25 | AD2: =CLASIFICACION!E25 | AE2: =CLASIFICACION!A25 | AF2: =CLASIFICACION!B25 | AG2: =CLASIFICACION!C25 | AH2: =CLASIFICACION!D25 | AI2: =CLASIFICACION!E25 | AJ2: =CLASIFICACION!A26 | AK2: =CLASIFICACION!B26 | AL2: =CLASIFICACION!C26 | AM2: =CLASIFICACION!D26 | AN2: =CLASIFICACION!E26 | AO2: =CLASIFICACION!A27 | AP2: =CLASIFICACION!B27 | AQ2: =CLASIFICACION!C27 | AR2: =CLASIFICACION!D27 | AS2: =CLASIFICACION!E27 | AT2: =CLASIFICACION!A28 | AU2: =CLASIFICACION!B28 | AV2: =CLASIFICACION!C28 | AW2: =CLASIFICACION!D28 | AX2: =CLASIFICACION!E28 | AY2: =CLASIFICACION!A29 | AZ2: =CLASIFICACION!B29 | BA2: =CLASIFICACION!C29 | BB2: =CLASIFICACION!D29 | BC2: =CLASIFICACION!E29 | BD2: =CLASIFICACION!A30 | BE2: =CLASIFICACION!B30 | BF2: =CLASIFICACION!C30 | BG2: =CLASIFICACION!D30 | BH2: =CLASIFICACION!E30 | BI2: =CLASIFICACION!A31 | BJ2: =CLASIFICACION!B31 | BK2: =CLASIFICACION!C31 | BL2: =CLASIFICACION!D31 | BM2: =CLASIFICACION!E31 | BN2: =CLASIFICACION!A32 | BO2: =CLASIFICACION!B32 | BP2: =CLASIFICACION!C32 | BQ2: =CLASIFICACION!D32 | BR2: =CLASIFICACION!E32

Sheet INPUTS RESULTADOS
A1: PARTIDO 1 | B1: RESULTADO 1 | C1: PARTIDO 2 | D1: RESULTADO 2 | E1: PARTIDO 3 | F1: RESULTADO 3 | G1: PARTIDO 4 | H1: RESULTADO 4 | I1: PARTIDO 5 | J1: RESULTADO 5 | K1: PARTIDO 6 | L1: RESULTADO 6 | M1: PARTIDO 7 | N1: RESULTADO 7 | O1: HUELVA COMERCIO P-1 | P1: HUELVA COMERCIO R-1 | Q1: HUELVA COMERCIO P-2 | R1: HUELVA COMERCIO R-2 | S1: HUELVA COMERCIO P-3 | T1: HUELVA COMERCIO R-3 | U1: HUELVA COMERCIO P-4 | V1: HUELVA COMERCIO R-4 | W1: HUELVA COMERCIO P-5 | X1: HUELVA COMERCIO R-5 | Y1: HUELVA COMERCIO P-6 | Z1: HUELVA COMERCIO R-6 | AA1: HUELVA COMERCIO P-7 | AB1: HUELVA COMERCIO R-7
A2: ='RESULTADOS JORNADA'!A2 | B2: ='RESULTADOS JORNADA'!B2 | C2: ='RESULTADOS JORNADA'!A3 | D2: ='RESULTADOS JORNADA'!B3 | E2: ='RESULTADOS JORNADA'!A4 | F2: ='RESULTADOS JORNADA'!B4 | G2: ='RESULTADOS JORNADA'!A5 | H2: ='RESULTADOS JORNADA'!B5 | I2: ='RESULTADOS JORNADA'!A6 | J2: ='RESULTADOS JORNADA'!B6 | K2: ='RESULTADOS JORNADA'!A7 | L2: ='RESULTADOS JORNADA'!B7 | M2: ='RESULTADOS JORNADA'!A8 | N2: ='RESULTADOS JORNADA'!B8 | O2: ='RESULTADOS JORNADA'!A13 | P2: ='RESULTADOS JORNADA'!B13 | Q2: ='RESULTADOS JORNADA'!A14 | R2: ='RESULTADOS JORNADA'!B14 | S2: ='RESULTADOS JORNADA'!A15 | T2: ='RESULTADOS JORNADA'!B15 | U2: ='RESULTADOS JORNADA'!A16 | V2: ='RESULTADOS JORNADA'!B16 | W2: ='RESULTADOS JORNADA'!A17 | X2: ='RESULTADOS JORNADA'!B17 | Y2: ='RESULTADOS JORNADA'!A18 | Z2: ='RESULTADOS JORNADA'!B18 | AA2: ='RESULTADOS JORNADA'!A19 | AB2: ='RESULTADOS JORNADA'!B19

Sheet INPUT ROTULOS PICK AND ROLL
A1: ROT PRESENTADOR 1 | B1: ROT PRESENTADOR 2 | C1: ROT PRESENTADOR 3 | D1: ROT PRESENTADOR 4 | E1: ROT PRESENTADOR 5 | F1: ROT PRESENTADOR 6 | G1: ROT PRESENTADOR 7 | H1: NOMB ROT INVITADO 1 | I1: CARGO ROT INVITADO 1 | J1: NOMB ROT INVITADO 2 | K1: CARGO ROT INVITADO 2 | L1: NOMB ROT INVITADO 3 | M1: CARGO ROT INVITADO 3 | N1: NOMB ROT INVITADO 4 | O1: CARGO ROT INVITADO 4 | P1: NOMB ROT INVITADO 5 | Q1: CARGO ROT INVITADO 5 | R1: NOMB ROT INVITADO 6 | S1: CARGO ROT INVITADO 6 | T1: NOMB ROT INVITADO 7 | U1: CARGO ROT INVITADO 7 | V1: NOMB ROT INVITADO 8 | W1: CARGO ROT INVITADO 8 | X1: NOMB ROT INVITADO 9 | Y1: CARGO ROT INVITADO 9 | Z1: NOMB ROT INVITADO 10 | AA1: CARGO ROT INVITADO 10 | AB1: NOMB ROT INVITADO 11 | AC1: CARGO ROT INVITADO 11 | AD1: NOMB ROT INVITADO 12 | AE1: CARGO ROT INVITADO 12 | AF1: NOMB ROT INVITADO 13 | AG1: CARGO ROT INVITADO 13 | AH1: CONEX TLF 1 NOMBRE | AI1: CONEX TLF 1 CARGO | AJ1: CONEX TLF 1 FOTO | AK1: CONEX TLF 2 NOMBRE | AL1: CONEX TLF 2 CARGO | AM1: CONEX TLF 2 FOTO
A2: ='PICK AND ROLL'!C7 | B2: ='PICK AND ROLL'!C10 | C2: ='PICK AND ROLL'!C13 | D2: ='PICK AND ROLL'!C16 | E2: ='PICK AND ROLL'!C19 | F2: ='PICK AND ROLL'!C22 | G2: ='PICK AND ROLL'!C25 | H2: ='PICK AND ROLL'!F9 | I2: ='PICK AND ROLL'!F10 | J2: ='PICK AND ROLL'!F13 | K2: ='PICK AND ROLL'!F14 | L2: ='PICK AND ROLL'!F17 | M2: ='PICK AND ROLL'!F18 | N2: ='PICK AND ROLL'!F21 | O2: ='PICK AND ROLL'!F22 | P2: ='PICK AND ROLL'!F25 | Q2: ='PICK AND ROLL'!F26 | R2: ='PICK AND ROLL'!F29 | S2: ='PICK AND ROLL'!F30 | T2: ='PICK AND ROLL'!F33 | U2: ='PICK AND ROLL'!F34 | V2: ='PICK AND ROLL'!F37 | W2: ='PICK AND ROLL'!F38 | X2: ='PICK AND ROLL'!F41 | Y2: ='PICK AND ROLL'!F42 | Z2: ='PICK AND ROLL'!F45 | AA2: ='PICK AND ROLL'!F46 | AB2: ='PICK AND ROLL'!F49 | AC2: ='PICK AND ROLL'!F50 | AD2: ='PICK AND ROLL'!F53 | AE2: ='PICK AND ROLL'!F54 | AF2: ='PICK AND ROLL'!F57 | AG2: ='PICK AND ROLL'!F58 | AH2: ='PICK AND ROLL'!F63 | AI2: ='PICK AND ROLL'!F64 | AJ2: ='PICK AND ROLL'!F65 | AK2: ='PICK AND ROLL'!F68 | AL2: ='PICK AND ROLL'!F69 | AM2: ='PICK AND ROLL'!F70

Sheet INPUT BANDAS PICK AND ROLL
A1: TI BANDA 1 | B1: TEXT BANDA 1 | C1: TI BANDA 2 | D1: TEXT BANDA 2 | E1: TI BANDA 3 | F1: TEXT BANDA 3 | G1: TI BANDA 4 | H1: TEXT BANDA 4 | I1: TI BANDA 5 | J1: TEXT BANDA 5 | K1: TI BANDA 6 | L1: TEXT BANDA 6 | M1: TI BANDA 7 | N1: TEXT BANDA 7 | O1: TI BANDA 8 | P1: TEXT BANDA 8 | Q1: TI BANDA 9 | R1: TEXT BANDA 9 | S1: TI BANDA 10 | T1: TEXT BANDA 10 | U1: TI BANDA 11 | V1: TEXT BANDA 11 | W1: TI BANDA 12 | X1: TEXT BANDA 12 | Y1: TI BANDA 13 | Z1: TEXT BANDA 13 | AA1: TI BANDA 14 | AB1: TEXT BANDA 14 | AC1: TI BANDA 15 | AD1: TEXT BANDA 15 | AE1: TI BANDA 16 | AF1: TEXT BANDA 16 | AG1: TI BANDA 17 | AH1: TEXT BANDA 17 | AI1: TI BANDA 18 | AJ1: TEXT BANDA 18 | AK1: TI BANDA 19 | AL1: TEXT BANDA 19 | AM1: TI BANDA 20 | AN1: TEXT BANDA 20
A2: ='PICK AND ROLL'!C30 | B2: ='PICK AND ROLL'!C31 | C2: ='PICK AND ROLL'!C34 | D2: ='PICK AND ROLL'!C35 | E2: ='PICK AND ROLL'!C38 | F2: ='PICK AND ROLL'!C39 | G2: ='PICK AND ROLL'!C42 | H2: ='PICK AND ROLL'!C43 | I2: ='PICK AND ROLL'!C46 | J2: ='PICK AND ROLL'!C47 | K2: ='PICK AND ROLL'!C50 | L2: ='PICK AND ROLL'!C51 | M2: ='PICK AND ROLL'!C54 | N2: ='PICK AND ROLL'!C55 | O2: ='PICK AND ROLL'!C58 | P2: ='PICK AND ROLL'!C59 | Q2: ='PICK AND ROLL'!C62 | R2: ='PICK AND ROLL'!C63 | S2: ='PICK AND ROLL'!C66 | T2: ='PICK AND ROLL'!C67 | U2: ='PICK AND ROLL'!C70 | V2: ='PICK AND ROLL'!C71 | W2: ='PICK AND ROLL'!C74 | X2: ='PICK AND ROLL'!C75 | Y2: ='PICK AND ROLL'!C78 | Z2: ='PICK AND ROLL'!C79 | AA2: ='PICK AND ROLL'!C82 | AB2: ='PICK AND ROLL'!C83 | AC2: ='PICK AND ROLL'!C86 | AD2: ='PICK AND ROLL'!C87 | AE2: ='PICK AND ROLL'!C90 | AF2: ='PICK AND ROLL'!C91 | AG2: ='PICK AND ROLL'!C94 | AH2: ='PICK AND ROLL'!C95 | AI2: ='PICK AND ROLL'!C98 | AJ2: ='PICK AND ROLL'!C99 | AK2: ='PICK AND ROLL'!C102 | AL2: ='PICK AND ROLL'!C103 | AM2: ='PICK AND ROLL'!C106 | AN2: ='PICK AND ROLL'!C107

Sheet INPUT FECHA Y LOCA PICK AND ROL
A1: FECHA HOY | B1: LOCA 1 | C1: LOCA 2 | D1: LOCA 3 | E1: LOCA 4 | F1: LOCA 5 | G1: LOCA 6 | H1: LOCA 7 | I1: LOCA 8 | J1: LOCA 9 | K1: LOCA 10 | L1: LOCA 11 | M1: LOCA 12 | N1: LOCA 13 | O1: LOCA 14 | P1: LOCA 15 | Q1: LOCA 16 | R1: LOCA 17 | S1: LOCA 18 | T1: LOCA 19 | U1: LOCA 20
A2: ='PICK AND ROLL'!C5 | B2: ='PICK AND ROLL'!F75 | C2: ='PICK AND ROLL'!F77 | D2: ='PICK AND ROLL'!F79 | E2: ='PICK AND ROLL'!F81 | F2: ='PICK AND ROLL'!F83 | G2: ='PICK AND ROLL'!F85 | H2: ='PICK AND ROLL'!F87 | I2: ='PICK AND ROLL'!F89 | J2: ='PICK AND ROLL'!F91 | K2: ='PICK AND ROLL'!F93 | L2: ='PICK AND ROLL'!F95 | M2: ='PICK AND ROLL'!F97 | N2: ='PICK AND ROLL'!F99 | O2: ='PICK AND ROLL'!F101 | P2: ='PICK AND ROLL'!F103 | Q2: ='PICK AND ROLL'!F105 | R2: ='PICK AND ROLL'!F107 | S2: ='PICK AND ROLL'!F109 | T2: ='PICK AND ROLL'!F111 | U2: ='PICK AND ROLL'!F113
